Submission ran but did not finish its execution due to the errors below. 
This does not mean the program did not execute however, it may or may not have produced some files or none: 

 Traceback (most recent call last):
  File "***Removed due to privacy***/decrypt_p98424rp/./decrypt_p98424rp.py", line 93, in <module>
    encryption(input_folder_string, output_folder_string, file)
  File "***Removed due to privacy***/decrypt_p98424rp/./decrypt_p98424rp.py", line 57, in encryption
    f1=open(input_folder + filename,"r")
FileNotFoundError: [Errno 2] No such file or directory: './test_files_encrypttest_file1.txt'

No files were created within the results folder. (This does not mean files were not created elsewhere)
