Submission ran but did not finish its execution due to the errors below. 
This does not mean the program did not execute however, it may or may not have produced some files or none: 

 Traceback (most recent call last):
  File "***Removed due to privacy***/decrypt_u43534sr/./decrypt_u43534sr.py", line 81, in <module>
    main()
  File "***Removed due to privacy***/decrypt_u43534sr/./decrypt_u43534sr.py", line 70, in main
    with open(encrypted, 'r') as e:
IsADirectoryError: [Errno 21] Is a directory: './test_files_encrypt'

No files were created within the results folder. (This does not mean files were not created elsewhere)
